<?xml version="1.0" encoding="utf-8"?>
<!-- =================================================================================== -->
<!-- |    This document was autogenerated by xacro from ikiwi_abila_42e_jf.urdf.xacro  | -->
<!-- |    EDITING THIS FILE BY HAND IS NOT RECOMMENDED                                 | -->
<!-- =================================================================================== -->
<robot name="ikiwi_abila">
  <!-- Init colour -->
  <material name="black">
    <color rgba="0.0 0.0 0.0 1.0"/>
  </material>
  <material name="dark">
    <color rgba="0.3 0.3 0.3 1.0"/>
  </material>
  <material name="light_black">
    <color rgba="0.4 0.4 0.4 1.0"/>
  </material>
  <material name="blue">
    <color rgba="0.0 0.0 0.8 1.0"/>
  </material>
  <material name="green">
    <color rgba="0.0 0.8 0.0 1.0"/>
  </material>
  <material name="grey">
    <color rgba="0.5 0.5 0.5 1.0"/>
  </material>
  <material name="orange">
    <color rgba="1.0 0.423529411765 0.0392156862745 1.0"/>
  </material>
  <material name="brown">
    <color rgba="0.870588235294 0.811764705882 0.764705882353 1.0"/>
  </material>
  <material name="red">
    <color rgba="0.8 0.0 0.0 1.0"/>
  </material>
  <material name="white">
    <color rgba="1.0 1.0 1.0 1.0"/>
  </material>
  <!--
  <xacro:arg name="laser_visual"  default="false"/>
  <xacro:arg name="camera_visual" default="false"/>
  <xacro:arg name="imu_visual"    default="false"/>
-->
  <gazebo reference="base_link">
    <material>Gazebo/DarkGrey</material>
  </gazebo>
  <gazebo reference="wheel_back_left_link">
    <mu1>1</mu1>
    <mu2>1</mu2>
    <kp>10000000.0</kp>
    <kd>1</kd>
    <minDepth>0.001</minDepth>
    <maxVel>10</maxVel>
    <fdir1>1 0 0</fdir1>
    <material>Gazebo/FlatBlack</material>
  </gazebo>
  <gazebo reference="wheel_back_right_link">
    <mu1>1</mu1>
    <mu2>1</mu2>
    <kp>10000000.0</kp>
    <kd>1</kd>
    <minDepth>0.001</minDepth>
    <maxVel>10</maxVel>
    <fdir1>1 0 0</fdir1>
    <material>Gazebo/FlatBlack</material>
  </gazebo>
  <gazebo reference="caster_wheel_front_support_left_link">
    <mu1>0.01</mu1>
    <mu2>0.01</mu2>
    <kp>1000000.0</kp>
    <kd>10.0</kd>
    <minDepth>0.001</minDepth>
    <maxVel>10.0</maxVel>
    <material>Gazebo/FlatBlack</material>
  </gazebo>
  <gazebo reference="caster_wheel_front_left_link">
    <mu1>0.72</mu1>
    <mu2>0.72</mu2>
    <kp>1000000.0</kp>
    <kd>10.0</kd>
    <minDepth>0.001</minDepth>
    <maxVel>10.0</maxVel>
    <material>Gazebo/FlatBlack</material>
  </gazebo>
  <gazebo reference="caster_wheel_front_support_right_link">
    <mu1>0.01</mu1>
    <mu2>0.01</mu2>
    <kp>1000000.0</kp>
    <kd>10.0</kd>
    <minDepth>0.001</minDepth>
    <maxVel>10.0</maxVel>
    <material>Gazebo/FlatBlack</material>
  </gazebo>
  <gazebo reference="caster_wheel_front_right_link">
    <mu1>0.72</mu1>
    <mu2>0.72</mu2>
    <kp>1000000.0</kp>
    <kd>10.0</kd>
    <minDepth>0.001</minDepth>
    <maxVel>10.0</maxVel>
    <material>Gazebo/FlatBlack</material>
  </gazebo>
  <gazebo reference="column_support_left_link">
    <material>Gazebo/DarkGrey</material>
  </gazebo>
  <gazebo reference="column_support_right_link">
    <material>Gazebo/DarkGrey</material>
  </gazebo>
  <gazebo reference="platform_upper_link">
    <material>Gazebo/DarkGrey</material>
  </gazebo>
  <gazebo reference="camera_platform_link">
    <material>Gazebo/DarkGrey</material>
  </gazebo>
  <gazebo reference="camera_support_link">
    <material>Gazebo/DarkGrey</material>
  </gazebo>
  <!--	IMU link
  <gazebo reference="imu_link">
    <sensor type="imu" name="imu">
      <always_on>true</always_on>
      <visualize>$(arg imu_visual)</visualize>
    </sensor>
    <material>Gazebo/Grey</material>
  </gazebo>
-->
  <gazebo>
    <plugin filename="libgazebo_ros_diff_drive.so" name="ikiwi_abila_controller">
      <commandTopic>cmd_vel</commandTopic>
      <odometryTopic>odom</odometryTopic>
      <odometryFrame>odom</odometryFrame>
      <odometrySource>world</odometrySource>
      <publishOdomTF>true</publishOdomTF>
      <robotBaseFrame>base_footprint</robotBaseFrame>
      <publishWheelTF>false</publishWheelTF>
      <publishTf>true</publishTf>
      <publishWheelJointState>true</publishWheelJointState>
      <legacyMode>false</legacyMode>
      <updateRate>30</updateRate>
      <leftJoint>wheel_back_left_joint</leftJoint>
      <rightJoint>wheel_back_right_joint</rightJoint>
      <wheelSeparation>0.325</wheelSeparation>
      <wheelDiameter>0.534</wheelDiameter>
      <wheelAcceleration>1</wheelAcceleration>
      <wheelTorque>20</wheelTorque>
      <rosDebugLevel>na</rosDebugLevel>
    </plugin>
  </gazebo>
  <!-- IMU plugin
  <gazebo>
    <plugin name="imu_plugin" filename="libgazebo_ros_imu.so">
      <alwaysOn>true</alwaysOn>
      <bodyName>imu_link</bodyName>
      <frameName>imu_link</frameName>
      <topicName>imu</topicName>
      <serviceName>imu_service</serviceName>
      <gaussianNoise>0.0</gaussianNoise>
      <updateRate>200</updateRate>
      <imu>
        <noise>
          <type>gaussian</type>
          <rate>
            <mean>0.0</mean>
            <stddev>2e-4</stddev>
            <bias_mean>0.0000075</bias_mean>
            <bias_stddev>0.0000008</bias_stddev>
          </rate>
          <accel>
            <mean>0.0</mean>
            <stddev>1.7e-2</stddev>
            <bias_mean>0.1</bias_mean>
            <bias_stddev>0.001</bias_stddev>
          </accel>
        </noise>
      </imu>
    </plugin>
  </gazebo>
-->
  <!-- Laser sensor
  <gazebo reference="base_scan">
    <material>Gazebo/FlatBlack</material>
    <sensor type="ray" name="lds_lfcd_sensor">
      <pose>0 0 0 0 0 0</pose>
      <visualize>$(arg laser_visual)</visualize>
      <update_rate>5</update_rate>
      <ray>
        <scan>
          <horizontal>
            <samples>360</samples>
            <resolution>1</resolution>
            <min_angle>0.0</min_angle>
            <max_angle>6.28319</max_angle>
          </horizontal>
        </scan>
        <range>
          <min>0.120</min>
          <max>3.5</max>
          <resolution>0.015</resolution>
        </range>
        <noise>
          <type>gaussian</type>
          <mean>0.0</mean>
          <stddev>0.01</stddev>
        </noise>
      </ray>
      <plugin name="gazebo_ros_lds_lfcd_controller" filename="libgazebo_ros_laser.so">
        <topicName>scan</topicName>
        <frameName>base_scan</frameName>
      </plugin>
    </sensor>
  </gazebo>
-->
  <!--
  <gazebo reference="camera_rgb_frame">
    <sensor type="depth" name="realsense_R200">
      <always_on>true</always_on>
      <visualize>$(arg camera_visual)</visualize>
      <camera>
          <horizontal_fov>1.3439</horizontal_fov>
          <image>
              <width>1920</width>
              <height>1080</height>
              <format>R8G8B8</format>
          </image>
          <depth_camera></depth_camera>
          <clip>
              <near>0.03</near>
              <far>100</far>
          </clip>
      </camera>
      <plugin name="camera_controller" filename="libgazebo_ros_openni_kinect.so">
        <baseline>0.2</baseline>
        <alwaysOn>true</alwaysOn>
        <updateRate>30.0</updateRate>
        <cameraName>camera</cameraName>
        <frameName>camera_rgb_optical_frame</frameName>
        <imageTopicName>rgb/image_raw</imageTopicName>
        <depthImageTopicName>depth/image_raw</depthImageTopicName>
        <pointCloudTopicName>depth/points</pointCloudTopicName>
        <cameraInfoTopicName>rgb/camera_info</cameraInfoTopicName>
        <depthImageCameraInfoTopicName>depth/camera_info</depthImageCameraInfoTopicName>
        <pointCloudCutoff>0.4</pointCloudCutoff>
            <hackBaseline>0.07</hackBaseline>
            <distortionK1>0.0</distortionK1>
            <distortionK2>0.0</distortionK2>
            <distortionK3>0.0</distortionK3>
            <distortionT1>0.0</distortionT1>
            <distortionT2>0.0</distortionT2>
        <CxPrime>0.0</CxPrime>
        <Cx>0.0</Cx>
        <Cy>0.0</Cy>
        <focalLength>0</focalLength>
        <hackBaseline>0</hackBaseline>
      </plugin>
    </sensor>
  </gazebo>
-->
  <!-- Base footprint link -->
  <link name="base_footprint"/>
  <joint name="base_joint" type="fixed">
    <parent link="base_footprint"/>
    <child link="base_link"/>
    <origin rpy="0 0 0" xyz="0 0 0.56"/>
  </joint>
  <link name="base_link">
    <visual>
      <origin xyz="0 0 0"/>
      <geometry>
        <box size="0.95 0.45 0.77"/>
      </geometry>
      <material name="light_black"/>
    </visual>
    <collision>
      <origin xyz="0 0 0"/>
      <geometry>
        <box size="0.95 0.45 0.77"/>
      </geometry>
    </collision>
    <inertial>
      <origin rpy="0 0 0" xyz="0 0 0"/>
      <mass value="50"/>
      <inertia ixx="3.1415341" ixy="0.0" ixz="0.0" iyy="3.1415341" iyz="0.0" izz="3.1415341"/>
    </inertial>
  </link>
  <joint name="brush_joint" type="fixed">
    <parent link="base_link"/>
    <child link="brush_link"/>
    <origin rpy="0 0 0" xyz="0.425 0 -0.47"/>
  </joint>
  <link name="brush_link">
    <visual>
      <origin xyz="0 0 0"/>
      <geometry>
        <box size="0.35 0.5 0.14"/>
      </geometry>
      <material name="light_black"/>
    </visual>
    <collision>
      <origin xyz="0 0 0"/>
      <geometry>
        <box size="0.35 0.5 0.14"/>
      </geometry>
    </collision>
    <inertial>
      <mass value="5"/>
      <inertia ixx="0.1" ixy="0" ixz="0" iyy="0.03" iyz="0" izz="0.1"/>
    </inertial>
  </link>
  <!-- Camera Intel Realsense D435i 

<xacro:sensor_d435 parent="camera_support_link" name="camera" topics_ns="camera">
   <origin xyz="${camera_support_length + 0.01} 0 ${camera_support_height/2 - 0.0015}" rpy="0 0 0" />
</xacro:sensor_d435> -->
  <!-- RPLidar -->
  <joint name="scan_joint" type="fixed">
    <parent link="base_link"/>
    <child link="base_scan"/>
    <origin rpy="0 0 0" xyz="-0.175 0 0.395"/>
  </joint>
  <link name="base_scan">
    <visual>
      <origin rpy="0 0 0" xyz="0 0 0"/>
      <geometry>
        <mesh filename="package://ikiwi_abila_description/meshes/sensors/rplidar_m.stl" scale="0.001 0.001 0.001"/>
      </geometry>
      <material name="dark"/>
    </visual>
    <collision>
      <origin rpy="0 0 0" xyz="0 0 0"/>
      <geometry>
        <cylinder length="0.0315" radius="0.055"/>
      </geometry>
    </collision>
    <inertial>
      <mass value="0.114"/>
      <origin xyz="0 0 0"/>
      <inertia ixx="1e-7" ixy="0.0" ixz="0.0" iyy="1e-7" iyz="0.0" izz="5e-8"/>
    </inertial>
  </link>
  <joint name="wheel_front_left_joint" type="continuous">
    <parent link="base_link"/>
    <child link="wheel_front_left_link"/>
    <axis xyz="0 0 1"/>
    <origin rpy="-1.57079632679 0 0" xyz="0.12 0.18 -0.475"/>
  </joint>
  <link name="wheel_front_left_link">
    <visual>
      <geometry>
        <cylinder length="0.045" radius="0.085"/>
      </geometry>
      <origin rpy="0 0 0" xyz="0 0 0"/>
      <material name="dark"/>
    </visual>
    <collision>
      <origin rpy="0 0 0" xyz="0 0 0"/>
      <geometry>
        <cylinder length="0.045" radius="0.085"/>
      </geometry>
    </collision>
    <inertial>
      <origin xyz="0 0 0"/>
      <mass value="3.4"/>
      <inertia ixx="0.0067" ixy="0" ixz="0" iyy="0.0123" iyz="0" izz="0.0067"/>
    </inertial>
  </link>
  <joint name="wheel_front_right_joint" type="continuous">
    <parent link="base_link"/>
    <child link="wheel_front_right_link"/>
    <axis xyz="0 0 1"/>
    <origin rpy="-1.57079632679 0 0" xyz="0.12 -0.18 -0.475"/>
  </joint>
  <link name="wheel_front_right_link">
    <visual>
      <geometry>
        <cylinder length="0.045" radius="0.085"/>
      </geometry>
      <origin rpy="0 0 0" xyz="0 0 0"/>
      <material name="dark"/>
    </visual>
    <collision>
      <origin rpy="0 0 0" xyz="0 0 0"/>
      <geometry>
        <cylinder length="0.045" radius="0.085"/>
      </geometry>
    </collision>
    <inertial>
      <origin xyz="0 0 0"/>
      <mass value="3.4"/>
      <inertia ixx="0.0067" ixy="0" ixz="0" iyy="0.0123" iyz="0" izz="0.0067"/>
    </inertial>
  </link>
  <link name="caster_wheel_back_support_left_link">
    <visual>
      <geometry>
        <cylinder length="0.01" radius="0.04"/>
      </geometry>
      <origin rpy="0 0 0" xyz="0 0 0"/>
    </visual>
    <collision>
      <geometry>
        <cylinder length="0.01" radius="0.04"/>
      </geometry>
    </collision>
    <inertial>
      <origin rpy="0 0 0" xyz="0 0 0"/>
      <mass value="1"/>
      <inertia ixx="5.4e-06" ixy="0" ixz="0" iyy="5.4e-06" iyz="0" izz="10e-06"/>
    </inertial>
  </link>
  <joint name="caster_wheel_back_support_left_joint" type="continuous">
    <parent link="base_link"/>
    <child link="caster_wheel_back_support_left_link"/>
    <axis xyz="0 0 1"/>
    <origin xyz="-0.30 0.1 -0.39"/>
  </joint>
  <joint name="caster_wheel_back_left_joint" type="continuous">
    <parent link="caster_wheel_back_support_left_link"/>
    <child link="caster_wheel_back_left_link"/>
    <axis xyz="0 0 1"/>
    <origin rpy="-1.57079632679 0 0 " xyz="0 0 -0.125"/>
  </joint>
  <link name="caster_wheel_back_left_link">
    <visual>
      <geometry>
        <cylinder length="0.035" radius="0.04"/>
      </geometry>
      <origin rpy="0 0 0" xyz="0 0 0"/>
      <material name="dark"/>
    </visual>
    <collision>
      <origin rpy="0 0 0" xyz="0 0 0"/>
      <geometry>
        <cylinder length="0.035" radius="0.04"/>
      </geometry>
    </collision>
    <inertial>
      <origin rpy="0 0 0" xyz="0 0 0"/>
      <mass value="0.3"/>
      <inertia ixx="150.162e-06" ixy="0" ixz="0" iyy="239.2636e-06" iyz="0" izz="150.162e-06"/>
    </inertial>
  </link>
  <link name="caster_wheel_back_support_right_link">
    <visual>
      <geometry>
        <cylinder length="0.01" radius="0.04"/>
      </geometry>
      <origin rpy="0 0 0" xyz="0 0 0"/>
    </visual>
    <collision>
      <geometry>
        <cylinder length="0.01" radius="0.04"/>
      </geometry>
    </collision>
    <inertial>
      <origin rpy="0 0 0" xyz="0 0 0"/>
      <mass value="1"/>
      <inertia ixx="5.4e-06" ixy="0" ixz="0" iyy="5.4e-06" iyz="0" izz="10e-06"/>
    </inertial>
  </link>
  <joint name="caster_wheel_back_support_right_joint" type="continuous">
    <parent link="base_link"/>
    <child link="caster_wheel_back_support_right_link"/>
    <axis xyz="0 0 1"/>
    <origin xyz="-0.30 -0.1 -0.39"/>
  </joint>
  <joint name="caster_wheel_back_right_joint" type="continuous">
    <parent link="caster_wheel_back_support_right_link"/>
    <child link="caster_wheel_back_right_link"/>
    <axis xyz="0 0 1"/>
    <origin rpy="-1.57079632679 0 0 " xyz="0 0 -0.125"/>
  </joint>
  <link name="caster_wheel_back_right_link">
    <visual>
      <geometry>
        <cylinder length="0.035" radius="0.04"/>
      </geometry>
      <origin rpy="0 0 0" xyz="0 0 0"/>
      <material name="dark"/>
    </visual>
    <collision>
      <origin rpy="0 0 0" xyz="0 0 0"/>
      <geometry>
        <cylinder length="0.035" radius="0.04"/>
      </geometry>
    </collision>
    <inertial>
      <origin rpy="0 0 0" xyz="0 0 0"/>
      <mass value="0.3"/>
      <inertia ixx="150.162e-06" ixy="0" ixz="0" iyy="239.2636e-06" iyz="0" izz="150.162e-06"/>
    </inertial>
  </link>
</robot>

